Error: prefix already exists: /home/ubuntu/miniconda/envs/_pipbuild_
Exception:
Traceback (most recent call last):
  File "/home/ubuntu/miniconda/envs/_pipbuild_/lib/python2.7/site-packages/pip/basecommand.py", line 223, in main
    status = self.run(options, args)
  File "/home/ubuntu/miniconda/envs/_pipbuild_/lib/python2.7/site-packages/pip/commands/install.py", line 268, in run
    wheel_cache
  File "/home/ubuntu/miniconda/envs/_pipbuild_/lib/python2.7/site-packages/pip/basecommand.py", line 268, in populate_requirement_set
    wheel_cache=wheel_cache
  File "/home/ubuntu/miniconda/envs/_pipbuild_/lib/python2.7/site-packages/pip/req/req_install.py", line 207, in from_line
    wheel_cache=wheel_cache)
  File "/home/ubuntu/miniconda/envs/_pipbuild_/lib/python2.7/site-packages/pip/req/req_install.py", line 66, in __init__
    req = pkg_resources.Requirement.parse(req)
  File "/home/ubuntu/miniconda/envs/_pipbuild_/lib/python2.7/site-packages/pip/_vendor/pkg_resources/__init__.py", line 2960, in parse
    reqs = list(parse_requirements(s))
  File "/home/ubuntu/miniconda/envs/_pipbuild_/lib/python2.7/site-packages/pip/_vendor/pkg_resources/__init__.py", line 2904, in parse_requirements
    "version spec")
  File "/home/ubuntu/miniconda/envs/_pipbuild_/lib/python2.7/site-packages/pip/_vendor/pkg_resources/__init__.py", line 2869, in scan_list
    raise ValueError(msg, line, "at", line[p:])
ValueError: ('Expected version spec in', 'python-dateutil==[0]', 'at', '==[0]')

Package search: {'_pypi_ordering': False, 'version': '1.0.3', 'name': 'analytics-python', 'summary': 'The hassle-free way to integrate analytics into any python application.'}
Creating standard recipe for analytics-python-1.0.3
Converting recipe in /home/ubuntu/pypi-conda-builds/analytics-python
package = analytics-python
   dependencies = [u'python-dateutil', u'requests', u'six']
Creating standard recipe for python-dateutil
Warning, the following versions were found for python-dateutil
2.4.2
2.4.1
2.4.0
2.3
2.2
2.1
2.0
1.5
1.4.1
1.4
1.2
1.1
1.0
0.5
0.4
0.3
0.1
Using 2.4.2
Use --version to specify a different version.
Using url https://pypi.python.org/packages/source/p/python-dateutil/python-dateutil-2.4.2.tar.gz (204 KB) for python-dateutil.
Downloading python-dateutil (use --no-download to skip this step)
Using cached download
Unpacking python-dateutil...
done
working in /tmp/tmpsKy5muconda_skeleton_python-dateutil-2.4.2.tar.gz
Fetching package metadata: ......
Solving package specifications: .patching file core.py
Hunk #1 succeeded at 168 with fuzz 2 (offset 2 lines).
Traceback (most recent call last):
  File "setup.py", line 7, in <module>
    from setuptools import setup
ImportError: No module named setuptools

Applying patch: '/tmp/tmpsKy5muconda_skeleton_python-dateutil-2.4.2.tar.gz/pypi-distutils.patch'
$PYTHONPATH = /tmp/tmpsKy5muconda_skeleton_python-dateutil-2.4.2.tar.gz/python-dateutil-2.4.2
Error: command failed: /home/ubuntu/miniconda/envs/_build/bin/python setup.py install

conda create -n _pipbuild_ --yes python pip
/home/ubuntu/miniconda/envs/_pipbuild_/bin/pip install python-dateutil==[0]
Error: Could not pip install python-dateutil==[0]
