An unexpected error has occurred, please consider sending the
following traceback to the conda GitHub issue tracker at:

    https://github.com/conda/conda-build/issues

Include the output of the command 'conda info' in your report.


Traceback (most recent call last):
  File "/home/ubuntu/miniconda/bin/conda-build", line 6, in <module>
    exec(compile(open(__file__).read(), __file__, 'exec'))
  File "/home/ubuntu/conda-build/bin/conda-build", line 5, in <module>
    sys.exit(main())
  File "/home/ubuntu/conda-build/conda_build/main_build.py", line 127, in main
    args_func(args, p)
  File "/home/ubuntu/conda-build/conda_build/main_build.py", line 346, in args_func
    args.func(args, p)
  File "/home/ubuntu/conda-build/conda_build/main_build.py", line 272, in execute
    m = MetaData(recipe_dir)
  File "/home/ubuntu/conda-build/conda_build/metadata.py", line 264, in __init__
    self.parse_again()
  File "/home/ubuntu/conda-build/conda_build/metadata.py", line 272, in parse_again
    self.meta = parse(get_contents(self.meta_path))
  File "/home/ubuntu/conda-build/conda_build/metadata.py", line 107, in parse
    res = yamlize(data)
  File "/home/ubuntu/miniconda/lib/python2.7/site-packages/conda/utils.py", line 120, in __call__
    value = self.func(*args, **kw)
  File "/home/ubuntu/conda-build/conda_build/metadata.py", line 96, in yamlize
    return yaml.load(data)
  File "/home/ubuntu/miniconda/lib/python2.7/site-packages/yaml/__init__.py", line 71, in load
    return loader.get_single_data()
  File "/home/ubuntu/miniconda/lib/python2.7/site-packages/yaml/constructor.py", line 39, in get_single_data
    return self.construct_document(node)
  File "/home/ubuntu/miniconda/lib/python2.7/site-packages/yaml/constructor.py", line 48, in construct_document
    for dummy in generator:
  File "/home/ubuntu/miniconda/lib/python2.7/site-packages/yaml/constructor.py", line 393, in construct_yaml_seq
    data.extend(self.construct_sequence(node))
  File "/home/ubuntu/miniconda/lib/python2.7/site-packages/yaml/constructor.py", line 118, in construct_sequence
    for child in node.value]
  File "/home/ubuntu/miniconda/lib/python2.7/site-packages/yaml/constructor.py", line 88, in construct_object
    data = constructor(self, node)
  File "/home/ubuntu/miniconda/lib/python2.7/site-packages/yaml/constructor.py", line 414, in construct_undefined
    node.start_mark)
yaml.constructor.ConstructorError: could not determine a constructor for the tag 'tag:yaml.org,2002:value'
  in "<unicode string>", line 41, column 7:
        - =
          ^
