Using url https://pypi.python.org/packages/source/s/supervisor/supervisor-3.1.3.tar.gz (382 KB) for supervisor.
Downloading supervisor (use --no-download to skip this step)
Unpacking supervisor...
done
working in /tmp/tmpWpV_vmconda_skeleton_supervisor-3.1.3.tar.gz
Fetching package metadata: ........
Solving package specifications: .patching file core.py
Hunk #1 succeeded at 168 with fuzz 2 (offset 2 lines).
An unexpected error has occurred, please consider sending the
following traceback to the conda GitHub issue tracker at:

    https://github.com/conda/conda-build/issues

Include the output of the command 'conda info' in your report.



The following NEW packages will be INSTALLED:

    numpy:  1.9.2-py27_0
    pyyaml: 3.11-py27_0 
    yaml:   0.1.4-0     

Linking packages ...
[                    ]|                                                  |   0%[yaml                ]|                                                  |   0%[numpy               ]|################                                  |  33%[pyyaml              ]|#################################                 |  66%[      COMPLETE      ]|##################################################| 100%
Applying patch: '/tmp/tmpWpV_vmconda_skeleton_supervisor-3.1.3.tar.gz/pypi-distutils.patch'
celementtree not found, trying cElementTree
0
Using url http://effbot.org/downloads#celementtree (0 B) for cElementTree.
Downloading cElementTree (use --no-download to skip this step)
Unpacking cElementTree...
Traceback (most recent call last):
  File "/home/hargup/anaconda/bin/conda-skeleton", line 6, in <module>
    exec(compile(open(__file__).read(), __file__, 'exec'))
  File "/home/hargup/210fs/conda-build/bin/conda-skeleton", line 5, in <module>
    sys.exit(main())
  File "/home/hargup/210fs/conda-build/conda_build/main_skeleton.py", line 201, in main
    args_func(args, p)
  File "/home/hargup/210fs/conda-build/conda_build/main_build.py", line 329, in args_func
    args.func(args, p)
  File "/home/hargup/210fs/conda-build/conda_build/main_skeleton.py", line 215, in execute
    pypi.main(args, parser)
  File "/home/hargup/210fs/conda-build/conda_build/pypi.py", line 388, in main
    get_package_metadata(args, package, d, data)
  File "/home/hargup/210fs/conda-build/conda_build/pypi.py", line 440, in get_package_metadata
    unpack(join(SRC_CACHE, d['filename']), tempdir)
  File "/home/hargup/210fs/conda-build/conda_build/pypi.py", line 653, in unpack
    raise Exception("not a valid source")
Exception: not a valid source
