Package search: {'_pypi_ordering': False, 'version': '1.4.0', 'name': 'traceback2', 'summary': 'Backports of the traceback module'}
Fetching package metadata: ....
Error: prefix already exists: /home/ubuntu/miniconda/envs/_pipbuild_
Collecting traceback2==1.4.0
  Downloading http://localhost/packages/3.4/t/traceback2/traceback2-1.4.0-py2.py3-none-any.whl
Collecting linecache2 (from traceback2==1.4.0)
  Downloading http://localhost/packages/3.5/l/linecache2/linecache2-1.0.0-py2.py3-none-any.whl
Installing collected packages: linecache2, traceback2
Successfully installed linecache2-1.0.0 traceback2-1.4.0
Fetching package metadata: ....

Package plan for package removal in environment /home/ubuntu/miniconda/envs/_pipbuild_:

The following packages will be REMOVED:

    openssl:    1.0.1k-1    
    pip:        7.0.3-py27_0
    python:     2.7.10-0    
    readline:   6.2-2       
    setuptools: 17.0-py27_0 
    sqlite:     3.8.4.1-1   
    system:     5.8-2       
    tk:         8.5.18-0    
    zlib:       1.2.8-0     

Unlinking packages ...
[                    ]|                                                  |   0%[openssl             ]|                                                  |   0%[pip                 ]|#####                                             |  11%[python              ]|###########                                       |  22%[readline            ]|################                                  |  33%[setuptools          ]|######################                            |  44%[sqlite              ]|###########################                       |  55%[system              ]|#################################                 |  66%[tk                  ]|######################################            |  77%[zlib                ]|############################################      |  88%[      COMPLETE      ]|##################################################| 100%
An unexpected error has occurred, please consider sending the
following traceback to the conda GitHub issue tracker at:

    https://github.com/conda/conda-build/issues

Include the output of the command 'conda info' in your report.


Creating standard recipe for traceback2-1.4.0
Error: directory already exists: ./traceback2

conda create -n _pipbuild_ --yes python pip
/home/ubuntu/miniconda/envs/_pipbuild_/bin/pip install traceback2==1.4.0
Getting dependencies...
package = traceback2
   dependencies = ['linecache2']
Creating standard recipe for linecache2
Converting recipe in /home/ubuntu/pypi-conda-builds/linecache2
Traceback (most recent call last):
  File "/home/ubuntu/miniconda/bin/conda-pipbuild", line 6, in <module>
    exec(compile(open(__file__).read(), __file__, 'exec'))
  File "/home/ubuntu/conda-build/bin/conda-pipbuild", line 5, in <module>
    sys.exit(main())
  File "/home/ubuntu/conda-build/conda_build/main_pipbuild.py", line 75, in main
    args_func(args, p)
  File "/home/ubuntu/conda-build/conda_build/main_build.py", line 346, in args_func
    args.func(args, p)
  File "/home/ubuntu/conda-build/conda_build/main_pipbuild.py", line 361, in execute
    build_package(package, version)
  File "/home/ubuntu/conda-build/conda_build/main_pipbuild.py", line 315, in build_package
    build_package(depend)
  File "/home/ubuntu/conda-build/conda_build/main_pipbuild.py", line 303, in build_package
    dependencies = convert_recipe(directory, package)
  File "/home/ubuntu/conda-build/conda_build/main_pipbuild.py", line 198, in convert_recipe
    d['homeurl'] = meta['about']['home']
KeyError: 'home'
