Warning, the following versions were found for ZODB3
3.11.0
3.11.0a3
3.11.0a2
3.11.0a1
3.10.5
3.10.4
3.10.3
3.10.2
3.10.1
3.10.0
3.10.0b8
3.10.0b7
3.10.0b6
3.10.0b5
3.10.0b4
3.10.0b3
3.10.0b2
3.10.0b1
3.10.0a2
3.10.0a1
3.9.7
3.9.6
3.9.5
3.9.4
3.9.3
3.9.2
3.9.1
3.9.0
3.9.0c3
3.9.0c2
3.9.0c1
3.9.0b5
3.9.0b4
3.9.0b3
3.9.0b2
3.9.0b1
3.9.0a12
3.9.0a11
3.9.0a10
3.9.0a9
3.9.0a7
3.9.0a6
3.9.0a5
3.9.0a4
3.9.0a3
3.9.0a2
3.9.0a1
3.8.6
3.8.5
3.8.4
3.8.3
3.8.3b1
3.8.2
3.8.1
3.8.1b9
3.8.1b8
3.8.1b7
3.8.1b6
3.8.1b5
3.8.1b4
3.8.1b3
3.8.1b2
3.8.1b1
3.8.0
3.8.0c1
3.8.0b4
3.8.0b3
3.8.0b2
3.8.0b1
3.8.0a1
3.7.2
3.7.0
3.6.0
3.5.1
3.5.0
3.4.2
3.3.1
3.2.10
3.1.5
Using 3.11.0
Use --version to specify a different version.
Using url https://pypi.python.org/packages/source/Z/ZODB3/ZODB3-3.11.0.tar.gz (54 KB) for ZODB3.
Downloading ZODB3 (use --no-download to skip this step)
Using cached download
Unpacking ZODB3...
done
working in /tmp/tmpVEexe4conda_skeleton_ZODB3-3.11.0.tar.gz
Fetching package metadata: ......
Solving package specifications: .patching file core.py
Hunk #1 succeeded at 168 with fuzz 2 (offset 2 lines).

Applying patch: '/tmp/tmpVEexe4conda_skeleton_ZODB3-3.11.0.tar.gz/pypi-distutils.patch'
Error: Could not parse: ZEO [test]
